Workbook

Sheet Synthèse
B2: IAT — Synthèse du pipeline
B3: Vue consolidée | Montants en FCFA | Tous les chiffres sont calculés depuis les autres onglets
B4: Mise à jour : 15/10/2026 (facturation : point comptable du 13/10/2026) · Cliquer sur un nom d’onglet pour ouvrir le détail
B6: INDICATEURS CLÉS DU PIPELINE
B7: Nombre d’affaires dans le pipeline | C7: =COUNTA('Pipeline global'!$D$9:$D$50) -> 37
B8: Montant total du pipeline | C8: =SUM('Pipeline global'!$L$9:$L$50) -> 453330882
B9: Montant pondéré (Montant × Closing) | C9: =SUM('Pipeline global'!$M$9:$M$50) -> 171217175
B10: Commission totale | C10: =SUM('Pipeline global'!$N$9:$N$50) -> 39000000
B11: % Rentabilité (Commission / Montant) | C11: =IFERROR(C10/C8,"") -> 0.086029877
B12: Montant gagné (M6) | C12: =SUMIFS('Pipeline global'!$L$9:$L$50,'Pipeline global'!$J$9:$J$50,"M6 – Gagné") -> 114686175
B13: Offres remises ou en signature (M4 + M5) | C13: =SUMIFS('Pipeline global'!$L$9:$L$50,'Pipeline global'!$J$9:$J$50,"M4 – Offre remise")+SUMIFS('Pipeline global'!$L$9:$L$50,'Pipeline global'!$J$9:$J$50,"M5 – Négociation / signature") -> 186335000
B14: Affaires encore à qualifier (M0) | C14: =COUNTIFS('Pipeline global'!$J$9:$J$50,"M0 – À qualifier") -> 18
B15: Affaires prioritaires (P1) | C15: =COUNTIFS('Pipeline global'!$P$9:$P$50,"P1") -> 10
B16: Actions du plan non terminées | C16: =COUNTIFS('Plan d’actions'!$C$9:$C$51,"<>",'Plan d’actions'!$H$9:$H$51,"<>Fait") -> 38
B18: FACTURATION, ENCAISSEMENTS ET RENOUVELLEMENTS (point comptable du 13/10/2026)
B19: Montant total facturé 2024-2026 | C19: =CNAM!G45+CNPS!G45+FER!G38+NSIA!G48+'Orange Business'!G37+NEURONES!G39 -> 299743360
B20: Total encaissé | C20: =CNAM!L45+CNPS!L45+FER!L38+NSIA!L48+'Orange Business'!L37+NEURONES!L39 -> 295243360
B21: Reste à encaisser | C21: =CNAM!M45+CNPS!M45+FER!M38+NSIA!M48+'Orange Business'!M37+NEURONES!M39 -> 4500000
B22: Taux d’encaissement | C22: =IFERROR(C20/C19,"") -> 0.98498716
B23: Montant récurrent annuel (base dernière facturation) | C23: =Renouvellements!F21 -> 143648024
B24: Renouvellements échus non renouvelés (montant) | C24: =SUMPRODUCT((LEFT(Renouvellements!$L$9:$L$20,4)="Échu")*Renouvellements!$F$9:$F$20) -> 28961849
B25: Nombre de contrats échus | C25: =SUMPRODUCT(--(LEFT(Renouvellements!$L$9:$L$20,4)="Échu")) -> 2
B26: Contrats à relancer sous 90 jours | C26: =SUMPRODUCT(--(LEFT(Renouvellements!$L$9:$L$20,10)="À relancer")) -> 0
B27: → Renouvellements
B29: CONTACTS (base clients CI + dirigeants identifiés)
B30: Contacts au total (onglet Contacts) | C30: =COUNTA(Contacts!$C$9:$C$428) -> 420
B31: Contacts rattachés au pipeline, aux clients ou aux cibles | C31: =SUMPRODUCT(--(Contacts!$J$9:$J$428<>"")) -> 210
B32: Contacts « Direction SI / digital » | C32: =COUNTIF(Contacts!$G$9:$G$428,"Direction SI / digital") -> 51
B33: Coordonnées à vérifier (numéros à 8 chiffres) | C33: =COUNTIF(Contacts!$K$9:$K$428,"Coordonnées à vérifier") -> 122
B34: RDV obtenus | C34: =COUNTIF(Contacts!$K$9:$K$428,"RDV obtenu") -> 0
B35: Dirigeants identifiés (recherche du 15/10/2026) | C35: =COUNTIF(Contacts!$N$9:$N$428,"Recherche dirigeants (web + LinkedIn, 15/10/2026)") -> 18
B36: → Contacts
B38: PAR TYPE DE COMPTE
B39: Type de compte | C39: Nb d’affaires | D39: Montant | E39: Montant pondéré | F39: Commission | G39: % Rentabilité | H39: Détail
B40: Client existant | C40: =COUNTIFS('Pipeline global'!$C$9:$C$50,B40) -> 12 | D40: =SUMIFS('Pipeline global'!$L$9:$L$50,'Pipeline global'!$C$9:$C$50,B40) -> 345330882 | E40: =SUMIFS('Pipeline global'!$M$9:$M$50,'Pipeline global'!$C$9:$C$50,B40) -> 171217175 | F40: =SUMIFS('Pipeline global'!$N$9:$N$50,'Pipeline global'!$C$9:$C$50,B40) -> 39000000 | G40: =IFERROR(F40/D40,"") -> 0.11293516 | H40: → Pipeline global
B41: Prospect | C41: =COUNTIFS('Pipeline global'!$C$9:$C$50,B41) -> 23 | D41: =SUMIFS('Pipeline global'!$L$9:$L$50,'Pipeline global'!$C$9:$C$50,B41) -> 108000000 | E41: =SUMIFS('Pipeline global'!$M$9:$M$50,'Pipeline global'!$C$9:$C$50,B41) -> 0 | F41: =SUMIFS('Pipeline global'!$N$9:$N$50,'Pipeline global'!$C$9:$C$50,B41) -> 0 | G41: =IFERROR(F41/D41,"") -> 0 | H41: → Solutions & prospects
B42: Appel d’offres | C42: =COUNTIFS('Pipeline global'!$C$9:$C$50,B42) -> 1 | D42: =SUMIFS('Pipeline global'!$L$9:$L$50,'Pipeline global'!$C$9:$C$50,B42) -> 0 | E42: =SUMIFS('Pipeline global'!$M$9:$M$50,'Pipeline global'!$C$9:$C$50,B42) -> 0 | F42: =SUMIFS('Pipeline global'!$N$9:$N$50,'Pipeline global'!$C$9:$C$50,B42) -> 0 | G42: =IFERROR(F42/D42,"") | H42: → Appels d’offres
B43: Partenaire / apporteur | C43: =COUNTIFS('Pipeline global'!$C$9:$C$50,B43) -> 1 | D43: =SUMIFS('Pipeline global'!$L$9:$L$50,'Pipeline global'!$C$9:$C$50,B43) -> 0 | E43: =SUMIFS('Pipeline global'!$M$9:$M$50,'Pipeline global'!$C$9:$C$50,B43) -> 0 | F43: =SUMIFS('Pipeline global'!$N$9:$N$50,'Pipeline global'!$C$9:$C$50,B43) -> 0 | G43: =IFERROR(F43/D43,"") | H43: → NEURONES
B44: TOTAL | C44: =SUM(C40:C43) -> 37 | D44: =SUM(D40:D43) -> 453330882 | E44: =SUM(E40:E43) -> 171217175 | F44: =SUM(F40:F43) -> 39000000 | G44: =IFERROR(F44/D44,"") -> 0.086029877
B46: COMPTES EXISTANTS — HISTORIQUE FACTURÉ (détail dans chaque onglet client)
...

Sheet Pipeline global
B2: IAT — Pipeline global
B3: Groupe IAG — Suivi AEC | Montants et commissions en FCFA | Toutes les affaires, y compris celles dont IAT n’est pas lead
B4: % Rentabilité = Commission / Montant · Montant pondéré = Montant × Closing · Jaune pâle = à compléter · Vert = repris d’une fiche client
B5: ← Retour à la synthèse
B7: AFFAIRES IAT
B8: N° | C8: Type de compte | D8: Entreprise / Projet | E8: Nature de l’affaire | F8: Solution / partenaire | G8: Origine (domaine) | H8: Lead | I8: Récurrent / ponctuel | J8: Étape | K8: Closing | L8: Montant (FCFA) | M8: Montant pondéré | N8: Commission (FCFA) | O8: % Rentabilité | P8: Priorité | Q8: Prochaine étape | R8: Échéance | S8: Commentaires | T8: Service IAT proposé | U8: Fiche détaillée | V8: Contact clé (base clients CI)
B9: 1 | C9: Client existant | D9: MD Participations | E9: Mise en place d'un ERP Groupe | F9: Odoo Community — périmètre et état de mobilisation à confirmer | G9: Approche directe (à valider) | H9: À confirmer | J9: Clôturé / en cessation | K9: 1 | L9: 14000000 | M9: =IF(OR(L9="",K9=""),"",L9*K9) -> 14000000 | O9: =IF(OR(L9="",N9=""),"",IFERROR(N9/L9,"")) | Q9: préavis en cours - établir contradictoirement la réalité de la mobilisation | S9: Affaire en cessation - cloture acté | T9: Intégration ERP et transformation des processus
B10: 2 | C10: Client existant | D10: Orange Burkina (via Orange Business) | E10: Migration Microsoft Exchange | F10: Microsoft Exchange / Microsoft 365 — via OC²S | G10: Consultation via partenaire (OC²S) | H10: À confirmer | I10: Ponctuel | J10: M5 – Négociation / signature | K10: =IF('Orange Business'!H42="","",'Orange Business'!H42) -> 0.6 | L10: =IF('Orange Business'!G42="","",'Orange Business'!G42) -> 41135000 | M10: =IF(OR(L10="",K10=""),"",L10*K10) -> 24681000 | O10: =IF(OR(L10="",N10=""),"",IFERROR(N10/L10,"")) | P10: P1 | Q10: Fixer une date de décision avec Judicaël KOUTOU (échéance actuellement non renseignée) · Identifier le décideur final côté Orange Burkina · Préparer une position de repli tarifaire avant concession | S10: Négociation en cours | M5/M6 - Négociation post-remise d'offre (à valider) | Offre remise depuis plus de 2 mois : nécessite une relance structurée. | T10: Migration de messagerie et environnement collaboratif | U10: → Orange Business
B11: 3 | C11: Client existant | D11: Orange Liberia (via Orange Business) | E11: Audit des assets SAM (Software Asset Management) | F11: Outils SAM à confirmer — expertise / mobilisation via OC²S | G11: Consultation via partenaire (OC²S) | H11: À confirmer | I11: Ponctuel | J11: M5 – Négociation / signature | K11: =IF('Orange Business'!H43="","",'Orange Business'!H43) -> 0.6 | L11: =IF('Orange Business'!G43="","",'Orange Business'!G43) -> 23000000 | M11: =IF(OR(L11="",K11=""),"",L11*K11) -> 13800000 | O11: =IF(OR(L11="",N11=""),"",IFERROR(N11/L11,"")) | P11: P1 | Q11: Fixer une date de décision · Clarifier les contraintes locales (Liberia : logistique, fiscalité, langue de restitution) · Sécuriser la disponibilité de l'auditeur SAM sur la fenêtre d'intervention | S11: Négociation en cours | M5/M6 - Négociation post-remise d'offre (à valider) | Affaire jumelle du dossier Orange Burkina : à traiter dans une même séquence de relance OC²S. | T11: Audit Software Asset Management (SAM) | U11: → Orange Business
B12: 4 | C12: Prospect | D12: KAYDAN | E12: À COMPLÉTER — intitulé de l'affaire à préciser | F12: Odoo CRM / modules de gestion — à valider après découverte | G12: A Valider | H12: Commercial IAT | J12: M0 – À qualifier | M12: =IF(OR(L12="",K12=""),"",L12*K12) | O12: =IF(OR(L12="",N12=""),"",IFERROR(N12/L12,"")) | P12: P2 | S12: Non qualifié — seul le contact est renseigné | M0 - À qualifier | Décision attendue : qualifier ou sortir du portefeuille. | T12: CRM, gestion commerciale et digitalisation immobilière — à qualifier
B13: 5 | C13: Client existant | D13: CNAM | E13: Renouvellement licences ManageEngine 2026 | F13: ManageEngine — modules et licences exacts à confirmer | G13: ManageEngine | H13: Commercial IAT | I13: Récurrent | J13: M6 – Gagné | K13: 1 | L13: =IF(CNAM!G41="","",CNAM!G41) -> 66309707 | M13: =IF(OR(L13="",K13=""),"",L13*K13) -> 66309707 | N13: =IF(CNAM!I41="","",CNAM!I41) -> 33000000 | O13: =IF(OR(L13="",N13=""),"",IFERROR(N13/L13,"")) -> 0.49766469 | P13: P3 | Q13: — | S13: Facturé le 27/02/2026 et soldé (compta). Historique : 69,8 M (2024) · 66,3 M (2025) · 66,3 M (2026). | T13: Support et gestion des services IT / licences | U13: → CNAM | V13: Direction : DG : Karim Bamba (confirmé) · DGA : Ahmed Tidiane Diomandé (confirmé)
B14: 6 | C14: Client existant | D14: CNAM | E14: Contrat de maintenance ManageEngine 2026 | F14: ManageEngine — modules et licences exacts à confirmer | G14: ManageEngine | H14: Commercial IAT | I14: Récurrent | J14: M6 – Gagné | K14: 1 | L14: =IF(CNAM!G42="","",CNAM!G42) -> 18000000 | M14: =IF(OR(L14="",K14=""),"",L14*K14) -> 18000000 | N14: =IF(CNAM!I42="","",CNAM!I42) -> 6000000 | O14: =IF(OR(L14="",N14=""),"",IFERROR(N14/L14,"")) -> 0.33333333 | P14: P2 | Q14: Relancer la direction financière CNAM pour le solde (facture jointe) | R14: 46357 | S14: Facturation trimestrielle de 4,5 M : 13,5 M encaissés, solde 4,5 M (compta). | T14: Support et gestion des services IT / licences | U14: → CNAM | V14: Direction : DG : Karim Bamba (confirmé) · DGA : Ahmed Tidiane Diomandé (confirmé)
B15: 7 | C15: Client existant | D15: CNAM | E15: Renouvellement licences ManageEngine 2027 | F15: ManageEngine — modules et licences exacts à confirmer | G15: ManageEngine | H15: Commercial IAT | I15: Récurrent | J15: M3 – Offre en préparation | L15: =IF(CNAM!G50="","",CNAM!G50) -> 66309707 | M15: =IF(OR(L15="",K15=""),"",L15*K15) | O15: =IF(OR(L15="",N15=""),"",IFERROR(N15/L15,"")) | P15: P2 | Q15: Préparer l’offre de renouvellement avant la relance J-90 | R15: 46355 | S15: Échéance 27/02/2027 · relance J-90 le 29/11/2026. Montant de base = dernière facturation. | T15: Support et gestion des services IT / licences | U15: → CNAM | V15: Direction : DG : Karim Bamba (confirmé) · DGA : Ahmed Tidiane Diomandé (confirmé)
B16: 8 | C16: Client existant | D16: CNPS | E16: Renouvellement licences ManageEngine 2026 | F16: ManageEngine — modules et licences exacts à confirmer | G16: ManageEngine | H16: Commercial IAT | I16: Récurrent | J16: M5 – Négociation / signature | L16: =IF(CNPS!G50="","",CNPS!G50) -> 22700000 | M16: =IF(OR(L16="",K16=""),"",L16*K16) | O16: =IF(OR(L16="",N16=""),"",IFERROR(N16/L16,"")) | P16: P1 | Q16: Relance commerciale + rendez-vous avec la DSI CNPS pour obtenir la décision | R16: 46318 | S16: Échu depuis le 10/02/2026 ; offre envoyée, attente client (compta). 22,7 M = montant évoqué en réunion, non chiffré dans le point comptable. Base 2025 : 21 578 849. | T16: Support et gestion des services IT / licences | U16: → CNPS | V16: Direction : DG : Denis Charles Kouassi (confirmé) · DGA chargé de l’exploitation : Idriss Traoré (à confirmer) · DSI : Thierry Bahi (à confirmer) Gballet BEUGRE — Directeur du Système d'Information (DSI) · Cel:(225)08305255 · g.beugre@cnps.ci (+7 autres dans l’onglet Contacts)
B17: 9 | C17: Client existant | D17: CNPS | E17: Offre ≈ 59 M envoyée — non encore validée | F17: À préciser | G17: Client existant | H17: Commercial IAT | J17: M4 – Offre remise | L17: =IF(CNPS!G51="","",CNPS!G51) -> 59000000 | M17: =IF(OR(L17="",K17=""),"",L17*K17) | O17: =IF(OR(L17="",N17=""),"",IFERROR(N17/L17,"")) | P17: P1 | Q17: Récupérer l’offre · fixer une date de décision | S17: Offre absente du point transmis par Désiré (réunion du 13/10). Objet et date d’envoi à compléter. Rattachement à la CNPS à confirmer (transcription « CNTS / CNT »). | U17: → CNPS | V17: Direction : DG : Denis Charles Kouassi (confirmé) · DGA chargé de l’exploitation : Idriss Traoré (à confirmer) · DSI : Thierry Bahi (à confirmer) Gballet BEUGRE — Directeur du Système d'Information (DSI) · Cel:(225)08305255 · g.beugre@cnps.ci (+7 autres dans l’onglet Contacts)
B18: 10 | C18: Client existant | D18: FER (Fond d'entretien Routier) | E18: Licences ManageEngine 2026 | F18: ManageEngine — produit et périmètre à confirmer | G18: ManageEngine | H18: Commercial IAT | I18: Récurrent | J18: M6 – Gagné | K18: 1 | L18: =IF(FER!G34="","",FER!G34) -> 28766400 | M18: =IF(OR(L18="",K18=""),"",L18*K18) -> 28766400 | O18: =IF(OR(L18="",N18=""),"",IFERROR(N18/L18,"")) | P18: P3 | Q18: Point de satisfaction avant la relance J-90 (26/03/2027) | S18: Nouveau client 2026 : facturé 28 766 400 le 24/06/2026, soldé (compta). Renouvellement le 24/06/2027. | T18: Licences et gestion des services IT | U18: → FER | V18: Direction : Directrice générale : Annick Tohé Lasmel (confirmé) · Directeur financier et comptable : Moussa Diarra (à confirmer)
B19: 11 | C19: Client existant | D19: FER (Fond d'entretien Routier) | E19: Sécurisation boîtes mails | F19: ManageEngine | G19: ManageEngine | H19: Commercial IAT | I19: Ponctuel | J19: M5 – Négociation / signature | K19: =IF(FER!H43="","",FER!H43) -> 0.9 | L19: =IF(FER!G43="","",FER!G43) -> 4500000 | M19: =IF(OR(L19="",K19=""),"",L19*K19) -> 4050000 | N19: 0 | O19: =IF(OR(L19="",N19=""),"",IFERROR(N19/L19,"")) -> 0 | P19: P1 | Q19: Vérifier avec la compta · planifier la formation prévue | S19: Ligne du pipeline d’origine (coût des ventes 1 065 000) non retrouvée dans la facturation transmise par la compta : vérifier si elle est incluse dans les 28,8 M ou reste à facturer. | T19: Licences et gestion des services IT | U19: → FER | V19: Direction : Directrice générale : Annick Tohé Lasmel (confirmé) · Directeur financier et comptable : Moussa Diarra (à confirmer)
B20: 12 | C20: Client existant | D20: NSIA (Assurances / Assurances Vie) | E20: Renouvellement licences ManageEngine 2026 | F20: ManageEngine | G20: Client existant | H20: Commercial IAT | I20: Récurrent | J20: M6 – Gagné | K20: 1 | L20: =IF(NSIA!G45="","",NSIA!G45) -> 1610068 | M20: =IF(OR(L20="",K20=""),"",L20*K20) -> 1610068 | O20: =IF(OR(L20="",N20=""),"",IFERROR(N20/L20,"")) | P20: P3 | Q20: Prochaine échéance 18/09/2027 | S20: Client depuis 2024 (compta) : 1,0 M (2024) · 1,0 M (2025) · 1,6 M (2026). Renouvelle chaque année en septembre. | T20: Support et gestion des services IT / licences | U20: → NSIA | V20: Direction : DG : Sonia Nadège Seka (à confirmer) · DGA : Gérard Gilles Akou (confirmé) · Directeur du réseau des particuliers : Jacques Avenie (à confirmer) NSIA PARTICIPATION : Gabriel COMOE-EDANOU — Directeur Des Opérations et de la Technologies Groupe · 0749595963 · gabriel.comoe-edanou@groupensia.com (+2 autres dans l’onglet Contacts) NSIA Banque : AMANGOUA Alexandre · 07 88 86 46 22 · alexandre.armangouah@groupensia.com (+3 autres dans l’onglet Contacts)
B21: 13 | C21: Partenaire / apporteur | D21: NEURONES | E21: Renouvellement licence WithSecure 2026 | F21: WithSecure | G21: WithSecure | H21: Commercial IAT | I21: Récurrent | J21: M3 – Offre en préparation | L21: =IF(NEURONES!G44="","",NEURONES!G44) | M21: =IF(OR(L21="",K21=""),"",L21*K21) | O21: =IF(OR(L21="",N21=""),"",IFERROR(N21/L21,"")) | P21: P1 | Q21: Relancer le fournisseur pour la cotation, puis émettre l’offre client | R21: 46309 | S21: Échu depuis le 21/08/2026 : blocage côté fournisseur, attente de cotation (compta). Base 2025 : 7 383 000 (soldé). | T21: Licences de sécurité des postes (endpoint) | U21: → NEURONES | V21: Direction : PDG : Luc de Chammard (confirmé) · DG délégué : Bertrand Ducurtil (à confirmer) · Directeur marketing et communication : Matthieu Vautier (à confirmer)
B22: 14 | C22: Prospect | D22: GIZ | E22: À COMPLÉTER — intitulé de l’affaire à préciser | H22: À confirmer | J22: M0 – À qualifier | M22: =IF(OR(L22="",K22=""),"",L22*K22) | O22: =IF(OR(L22="",N22=""),"",IFERROR(N22/L22,"")) | P22: P3 | S22: Aucune donnée dans le fichier d’origine.
B23: 15 | C23: Appel d’offres | D23: Le Médiateur de la République de Côte d'Ivoire (à valider) | E23: Plateforme e-Médiation (via OC²S) | F23: Plateforme e-Médiation via OC²S — rôle, solution et périmètre à confirmer | G23: Appel d'offres public (à valider) | H23: À confirmer | J23: M0 – À qualifier | M23: =IF(OR(L23="",K23=""),"",L23*K23) | O23: =IF(OR(L23="",N23=""),"",IFERROR(N23/L23,"")) | P23: P2 | Q23: Compléter la fiche : entité porteuse, montant, calendrier de l'AO, pièces attendues · Confirmer le rôle d'OC²S (mandataire / sous-traitant) et formaliser l'accord de groupement · Verrouiller le rétroplanning de dépôt | S23: En cours de montage (à valider) — données non renseignées dans le fichier source | M0 - À qualifier | Ligne présente dans le fichier sous l'intitulé « OCCS EMEDIATION » sans aucune donnée. Pré-renseignée ici sur la base du contexte connu : À VALIDER avant diffusion. | T23: Plateforme de e-médiation et intégration applicative — à valider | U23: → Appels d’offres
B24: 16 | C24: Prospect | D24: AGITECH (AG Tech Afrik) | E24: Solution MDM — Mobile Device Management (40 terminaux) | F24: Solution MDM à sélectionner; ManageEngine Endpoint Central à évaluer, sans engagement à ce stade | G24: Demande de cotation — affaire indirecte (client final via AGITECH) | H24: Commercial IAT | I24: Ponctuel | J24: M1 – Besoin identifié | M24: =IF(OR(L24="",K24=""),"",L24*K24) | O24: =IF(OR(L24="",N24=""),"",IFERROR(N24/L24,"")) | P24: P1 | Q24: QUICK WIN : produire la cotation sous 5 jours ouvrés · Sélectionner l'éditeur MDM et obtenir le prix partenaire · Clarifier l'identité du client final et le potentiel d'extension du parc | S24: Demande de cotation reçue — offre non remise | M1 - Besoin identifié / demande d'étude | Faible montant mais forte valeur d'entrée : porte d'accès au client final et à un partenaire prescripteur. | T24: Gestion des terminaux mobiles (MDM) — cotation
B25: 17 | C25: Prospect | D25: SIFCA | E25: Transformation digitale et pilotage des processus métiers | F25: Odoo Community / Microsoft Power Platform ou BI — à valider selon architecture existante | G25: Prospection directe (à initier) | H25: Commercial IAT | J25: M0 – À qualifier | M25: =IF(OR(L25="",K25=""),"",L25*K25) | O25: =IF(OR(L25="",N25=""),"",IFERROR(N25/L25,"")) | P25: P3 | Q25: Identifier DSI / finance / opérations · Obtenir un rendez-vous de découverte · Vérifier les systèmes en place et les achats en cours | S25: Approche grands comptes : cartographier les filiales et identifier un besoin métier prioritaire; ne pas présumer d’un remplacement ERP. | M0 - À qualifier | Prospect nouveau : besoin, budget, décideur et calendrier non confirmés. | T25: Transformation des processus, ERP et reporting
B26: 18 | C26: Prospect | D26: PALMCI | E26: Pilotage opérationnel, stocks et maintenance | F26: Odoo / outil de gestion des interventions / Microsoft BI — choix à confirmer après cadrage | G26: Prospection directe (à initier) | H26: Commercial IAT | J26: M0 – À qualifier | M26: =IF(OR(L26="",K26=""),"",L26*K26) | O26: =IF(OR(L26="",N26=""),"",IFERROR(N26/L26,"")) | P26: P3 | Q26: Contacter DSI et direction industrielle · Identifier un processus pilote · Confirmer contraintes sites et intégrations | S26: Hypothèse de besoin à valider; éviter toute proposition de remplacement du système industriel sans audit. | M0 - À qualifier | Prospect nouveau : besoin, budget, décideur et calendrier non confirmés. | T26: Gestion opérationnelle, maintenance et reporting
B27: 19 | C27: Prospect | D27: Olam Cocoa Processing Abidjan | E27: Pilotage des flux et automatisation des processus support | F27: Microsoft Power Platform / outils BI / intégration API — à confirmer après découverte | G27: Prospection directe (à initier) | H27: Commercial IAT | J27: M0 – À qualifier | M27: =IF(OR(L27="",K27=""),"",L27*K27) | O27: =IF(OR(L27="",N27=""),"",IFERROR(N27/L27,"")) | P27: P3 | Q27: Identifier IT / supply chain / opérations · Qualifier le processus cible et le décideur · Vérifier fournisseurs en place | S27: Prospecter un processus périphérique et mesurable plutôt que les systèmes industriels critiques. | M0 - À qualifier | Prospect nouveau : besoin, budget, décideur et calendrier non confirmés. | T27: Automatisation, intégration et reporting | V27: Alain MOGO — DSI Groupe · 05 06 72 72 82 (+1 autre dans l’onglet Contacts)
B28: 20 | C28: Prospect | D28: PROSUMA | E28: Automatisation, gestion documentaire et reporting | F28: Microsoft 365 / Power Automate / Power BI — licences et architecture à vérifier | G28: Prospection directe (à initier) | H28: Commercial IAT | J28: M0 – À qualifier | M28: =IF(OR(L28="",K28=""),"",L28*K28) | O28: =IF(OR(L28="",N28=""),"",IFERROR(N28/L28,"")) | P28: P3 | Q28: Identifier DSI / finance / opérations · Proposer un atelier de découverte · Quantifier le processus manuel ciblé | S28: Chercher un cas d’usage transversal et borné; ne pas présumer d’un besoin de refonte globale. | M0 - À qualifier | Prospect nouveau : besoin, budget, décideur et calendrier non confirmés. | T28: Automatisation des processus et pilotage décisionnel | V28: Direction : Dirigeants (DG / PDG) : Abou Kassam et Karim Fakhry (confirmé) · DSI : Moussa Touré (à confirmer) Moussa TOURE — DSI · D : (+225) 27 21 25 34 16 / 07 57 25 79 54 · Moussa.Toure@prosuma.ci (+3 autres dans l’onglet Contacts)
B29: 21 | C29: Prospect | D29: Africa Global Logistics Côte d’Ivoire (AGL) | E29: Automatisation des workflows et services IT complémentaires | F29: Microsoft 365 / Power Platform / cloud partenaire — à confirmer selon exigences client | G29: Prospection directe (à initier) | H29: Commercial IAT | J29: M0 – À qualifier | M29: =IF(OR(L29="",K29=""),"",L29*K29) | O29: =IF(OR(L29="",N29=""),"",IFERROR(N29/L29,"")) | P29: P3 | Q29: Identifier DSI / opérations · Rechercher un lot complémentaire · Qualifier exigences de sécurité et références requises | S29: Cibler les fonctions support ou un lot externalisable sans intervenir d’emblée sur les systèmes logistiques critiques. | M0 - À qualifier | Prospect nouveau : besoin, budget, décideur et calendrier non confirmés. | T29: Workflows, intégration applicative et services d’infrastructure | V29: Dimitri ADON — Chef de Département Infrastructure et Technique · 07 59 92 72 42 / 07 47 72 63 44 · Dimitri.ADON@bollore.com
B30: 22 | C30: Prospect | D30: SODECI | E30: Digitalisation des processus support et maintenance IT | F30: ManageEngine / Microsoft Power Platform — modules à confirmer | G30: Prospection directe (à initier) | H30: Commercial IAT | J30: M0 – À qualifier | M30: =IF(OR(L30="",K30=""),"",L30*K30) | O30: =IF(OR(L30="",N30=""),"",IFERROR(N30/L30,"")) | P30: P3 | Q30: Identifier DSI / achats / moyens généraux · Vérifier procédure de référencement fournisseur · Proposer un atelier de cadrage | S30: Approche ciblée; qualifier procédures d’achat, exigences de sécurité et contrats existants. | M0 - À qualifier | Prospect nouveau : besoin, budget, décideur et calendrier non confirmés. | T30: Automatisation, gestion des services IT et reporting | V30: Hermann N'ganza — DTI · 0506323236 · hermann.nganza@gs2e.ci (+6 autres dans l’onglet Contacts)
B31: 23 | C31: Prospect | D31: CIE | E31: Automatisation des workflows et résilience IT | F31: ManageEngine / Microsoft / partenaire cybersécurité — périmètre à confirmer | G31: Prospection directe (à initier) | H31: Commercial IAT | J31: M0 – À qualifier | M31: =IF(OR(L31="",K31=""),"",L31*K31) | O31: =IF(OR(L31="",N31=""),"",IFERROR(N31/L31,"")) | P31: P3 | Q31: Identifier DSI / opérations / achats · Qualifier le périmètre non critique · Vérifier exigences et procédure de consultation | S31: Ne pas proposer de changement sur systèmes critiques sans références et validation technique appropriées. | M0 - À qualifier | Prospect nouveau : besoin, budget, décideur et calendrier non confirmés. | T31: Services IT, continuité d’activité et automatisation | V31: CIE : Tanoh Hermann · 0709332615 · batanoh@cie.ci GS2E : Hermann N'ganza — DTI · 0506323236 · hermann.nganza@gs2e.ci (+6 autres dans l’onglet Contacts)
B32: 24 | C32: Prospect | D32: Air Côte d’Ivoire | E32: Services IT complémentaires, gestion documentaire et résilience | F32: Microsoft 365 / outils de workflow / partenaire cybersécurité — à valider | G32: Prospection directe (à initier) | H32: Commercial IAT | J32: M0 – À qualifier | M32: =IF(OR(L32="",K32=""),"",L32*K32) | O32: =IF(OR(L32="",N32=""),"",IFERROR(N32/L32,"")) | P32: P3 | Q32: Identifier DSI / sécurité / achats · Confirmer les lots accessibles et références exigées · Évaluer calendrier d’achat | S32: Cibler un besoin périphérique au SI aéronautique; qualification de sécurité obligatoire. | M0 - À qualifier | Prospect nouveau : besoin, budget, décideur et calendrier non confirmés. | T32: Automatisation, gestion documentaire et résilience IT | V32: Martial DIABATE — RSI · 07 69 55 95 70 · ma.diabate@aircotedivoire.com (+3 autres dans l’onglet Contacts)
B33: 25 | C33: Prospect | D33: GIG (Groupement d’Industries Générales) | E33: Gestion des stocks, achats et opérations | F33: Odoo Community — uniquement si adéquation confirmée après audit | G33: Prospection directe (à initier) | H33: Commercial IAT | J33: M0 – À qualifier | M33: =IF(OR(L33="",K33=""),"",L33*K33) | O33: =IF(OR(L33="",N33=""),"",IFERROR(N33/L33,"")) | P33: P3 | Q33: Vérifier l’identité et le périmètre de l’entreprise · Identifier dirigeant / finance / opérations · Proposer entretien découverte | S33: Prospect à qualifier; confirmer l’entité exacte, les activités et le système existant avant proposition. | M0 - À qualifier | Prospect nouveau : besoin, budget, décideur et calendrier non confirmés. | T33: ERP et transformation des processus
B34: 26 | C34: Prospect | D34: Banian Group | E34: Gestion interfiliales, CRM et tableaux de bord | F34: Odoo CRM / Microsoft Power Platform / BI — à définir après cadrage | G34: Prospection directe (à initier) | H34: Commercial IAT | J34: M0 – À qualifier | M34: =IF(OR(L34="",K34=""),"",L34*K34) | O34: =IF(OR(L34="",N34=""),"",IFERROR(N34/L34,"")) | P34: P3 | Q34: Cartographier les filiales et décideurs · Identifier un pilote · Vérifier systèmes et priorités budgétaires | S34: Approche groupe, mais qualification filiale par filiale et décisionnaire par décisionnaire. | M0 - À qualifier | Prospect nouveau : besoin, budget, décideur et calendrier non confirmés. | T34: CRM, workflows et pilotage multi-entités
B35: 27 | C35: Prospect | D35: CDC-CI (Caisse des Dépôts et Consignations de Côte d’Ivoire) | E35: Digitalisation des processus et gestion documentaire | F35: Microsoft 365 / Power Platform / GED partenaire — conformité et périmètre à confirmer | G35: Prospection directe (à initier) | H35: Commercial IAT | J35: M0 – À qualifier | M35: =IF(OR(L35="",K35=""),"",L35*K35) | O35: =IF(OR(L35="",N35=""),"",IFERROR(N35/L35,"")) | P35: P3 | Q35: Surveiller les avis et manifestations d’intérêt · Vérifier critères d’éligibilité et références · Identifier le service demandeur | S35: Veille sur les consultations officielles; aucune opportunité d’appel d’offres présumée ouverte. | M0 - À qualifier | Prospect nouveau : besoin, budget, décideur et calendrier non confirmés. | T35: Gestion documentaire, automatisation et reporting
B36: 28 | C36: Prospect | D36: MTN Côte d’Ivoire | E36: Automatisation métiers et solutions numériques complémentaires | F36: Microsoft / API / plateforme IA sécurisée — technologie à sélectionner après qualification | G36: Prospection directe (à initier) | H36: Commercial IAT | J36: M0 – À qualifier | M36: =IF(OR(L36="",K36=""),"",L36*K36) | O36: =IF(OR(L36="",N36=""),"",IFERROR(N36/L36,"")) | P36: P3 | Q36: Identifier direction IT / innovation / opérations · Cartographier contrats et partenaires en place · Qualifier un cas d’usage | S36: Compte stratégique avec écosystème technologique mature; chercher un besoin précis et une porte d’entrée partenaire. | M0 - À qualifier | Prospect nouveau : besoin, budget, décideur et calendrier non confirmés. | T36: Automatisation, intégration applicative et IA métier | V36: MTN : Corinne N’TAPKE — Manager Technology Process · 22505238080 · Corinne.n’tapke@mtn.com (+10 autres dans l’onglet Contacts) MTN BUSINESS : Hervé ZANDO · 22505044448 · Herve.Zando@mtn.com (+3 autres dans l’onglet Contacts)
B37: 29 | C37: Client existant | D37: Orange Business — E-Agri | E37: Plateforme E-Agri (commercialisation de produits vivriers) | F37: Développement plateforme — partenaires | G37: Orange Business | H37: À confirmer | I37: Récurrent | J37: M6 – Gagné | M37: =IF(OR(L37="",K37=""),"",L37*K37) | O37: =IF(OR(L37="",N37=""),"",IFERROR(N37/L37,"")) | P37: P2 | Q37: Faire le point sur l’avancement du développement par les partenaires | S37: Contrat de réalisation + revenue sharing avec Orange en exploitation (réunion du 13/10). Montant et avancement à compléter ; aucune facturation dans le point comptable. | T37: Développement de plateforme numérique | U37: → Orange Business | V37: Mame DIOP — DSI · 22507799662 · mame.diopba@orange.com (+7 autres dans l’onglet Contacts)
B38: 30 | C38: Prospect | D38: Client à préciser (projet digitalisation) | E38: Digitalisation du pôle opérationnel | F38: Développement sur mesure (à transformer en produit) | G38: Approche directe | H38: À confirmer | I38: Récurrent | J38: M5 – Négociation / signature | L38: 36000000 | M38: =IF(OR(L38="",K38=""),"",L38*K38) | O38: =IF(OR(L38="",N38=""),"",IFERROR(N38/L38,"")) | P38: P1 | Q38: RDV du 19/10 pour finaliser le cahier des charges | R38: 46314 | S38: Accord de principe donné. 36 M payés 1 M / mois sur 3 ans. Cahier des charges presque finalisé. Hypothèse : client = groupe PROSUMA (le « grand frère Aboukassar » cité en réunion ≈ Abou Kassam, codirigeant de PROSUMA ; entrepôts sec / frais cohérents avec la distribution) — à confirmer. | T38: Digitalisation des processus
B39: 31 | C39: Prospect | D39: Client à préciser (projet digitalisation) | E39: Prisme + portail (complément) | F39: Développement sur mesure | G39: Approche directe | H39: À confirmer | I39: Récurrent | J39: M3 – Offre en préparation | L39: 72000000 | M39: =IF(OR(L39="",K39=""),"",L39*K39) | O39: =IF(OR(L39="",N39=""),"",IFERROR(N39/L39,"")) | P39: P1 | Q39: Finaliser la cotation · la valider ensemble · l’émettre sur papier à en-tête Infinity | S39: Hypothèse : ≈ 3 M / mois sur 24 mois (option paiement comptant à chiffrer). Argument : remplace la saisie manuelle de ≈ 20 comptables juniors. | T39: Digitalisation des processus
B40: 32 | C40: Prospect | D40: Client à préciser (projet digitalisation) | E40: Projets entrepôts (sec / frais) | F40: À définir | G40: Approche directe | H40: À confirmer | J40: M0 – À qualifier | M40: =IF(OR(L40="",K40=""),"",L40*K40) | O40: =IF(OR(L40="",N40=""),"",IFERROR(N40/L40,"")) | P40: P3 | Q40: Qualifier après le lancement du projet de digitalisation | S40: Évoqué par le client comme projet suivant.
B41: 33 | C41: Prospect | D41: Ministère des Transports | E41: Gestion de flotte automobile | F41: Éditeur partenaire (boîtier + 4G + plateforme) | G41: Prospection directe | H41: À confirmer | J41: M1 – Besoin identifié | M41: =IF(OR(L41="",K41=""),"",L41*K41) | O41: =IF(OR(L41="",N41=""),"",IFERROR(N41/L41,"")) | P41: P2 | Q41: Obtenir des tests sur les véhicules de l’entreprise avant de se positionner | S41: Solution à challenger techniquement ; cible : grands parcs automobiles (PND). | T41: Gestion de flotte
B42: 34 | C42: Prospect | D42: SGI (BOA, BNI…) | E42: Plateforme d’investissement Wari+ (marque blanche) | F42: Wari+ — partenariat à signer | G42: Via le partenaire éditeur | H42: À confirmer | J42: M1 – Besoin identifié | M42: =IF(OR(L42="",K42=""),"",L42*K42) | O42: =IF(OR(L42="",N42=""),"",IFERROR(N42/L42,"")) | P42: P1 | Q42: Signer le partenariat · préparer la démo du salon | R42: 46317 | S42: Prix plancher éditeur 45 M, revenue sharing au-delà. Démo interactive prévue au Salon de l’Épargne (22-23/10). | T42: Plateforme front-office d’investissement | V42: BOA BANK CI : johnson YAPI — DSI GROUPE · 221 07 77 482 0450 · jyapi@boaholding.com (+7 autres dans l’onglet Contacts) BNI : Noufe — DSI · 07 07620719 · anoufe@bni.ci (+6 autres dans l’onglet Contacts)
...

Sheet Renouvellements
B2: IAT — Renouvellements
B3: Contrats récurrents (licences et maintenance) · Source : point comptable du 13/10/2026 · Montants en FCFA
B4: Prochaine échéance = dernière facturation + 12 mois · Jaune pâle = à renseigner · Vert = repris d’une fiche client · colonnes calculées : échéance, jours, relances, alerte
B5: ← Retour à la synthèse
B7: CALENDRIER ET SUIVI DES RELANCES DE RENOUVELLEMENT
B8: N° | C8: Client | D8: Contrat / produit | E8: Dernière facturation | F8: Dernier montant facturé | G8: Historique facturé | H8: Prochaine échéance | I8: Jours restants | J8: Relance J-90 | K8: Relance J-30 | L8: Alerte | M8: Statut du renouvellement | N8: Porteur | O8: Date dernière relance | P8: Prochaine action | Q8: Commentaire | R8: Fiche
B9: 1 | C9: CNPS | D9: Licences ManageEngine | E9: =IF(ISNUMBER(CNPS!F41),CNPS!F41,"N/A") -> 45698 | F9: =IF(CNPS!G41="","",CNPS!G41) -> 21578849 | G9: 2025 : 21,6 M | H9: =IF(ISNUMBER(E9),EDATE(E9,12),"") -> 46063 | I9: =IF(ISNUMBER(H9),H9-TODAY(),"") -> -251 | J9: =IF(ISNUMBER(H9),H9-90,"") -> 45973 | K9: =IF(ISNUMBER(H9),H9-30,"") -> 46033 | L9: =IF(C9="","",IF(M9="Renouvelé","Renouvelé",IF(M9="Perdu","Perdu",IF(NOT(ISNUMBER(H9)),"Date à confirmer",IF(H9<TODAY(),"Échu - urgent",IF(H9-TODAY()<=90,"À relancer (≤ 90 j)","À venir")))))) -> Échu - urgent | M9: Offre envoyée | P9: Relance commerciale + rendez-vous avec la DSI CNPS pour obtenir la décision | Q9: Offre 2026 en attente de retour CNPS. Échéance dépassée. | R9: → CNPS
B10: 2 | C10: NEURONES | D10: Licence WithSecure | E10: =IF(ISNUMBER(NEURONES!F35),NEURONES!F35,"N/A") -> 45890 | F10: =IF(NEURONES!G35="","",NEURONES!G35) -> 7383000 | G10: 2025 : 7,4 M | H10: =IF(ISNUMBER(E10),EDATE(E10,12),"") -> 46255 | I10: =IF(ISNUMBER(H10),H10-TODAY(),"") -> -59 | J10: =IF(ISNUMBER(H10),H10-90,"") -> 46165 | K10: =IF(ISNUMBER(H10),H10-30,"") -> 46225 | L10: =IF(C10="","",IF(M10="Renouvelé","Renouvelé",IF(M10="Perdu","Perdu",IF(NOT(ISNUMBER(H10)),"Date à confirmer",IF(H10<TODAY(),"Échu - urgent",IF(H10-TODAY()<=90,"À relancer (≤ 90 j)","À venir")))))) -> Échu - urgent | M10: Attente cotation fournisseur | P10: Relancer le fournisseur pour la cotation, puis émettre l’offre | Q10: Blocage côté fournisseur. Échéance dépassée. | R10: → NEURONES
B11: 3 | C11: CNAM | D11: Licences ManageEngine | E11: =IF(ISNUMBER(CNAM!F41),CNAM!F41,"N/A") -> 46080 | F11: =IF(CNAM!G41="","",CNAM!G41) -> 66309707 | G11: 2024 : 69,8 M · 2025 : 66,3 M · 2026 : 66,3 M | H11: =IF(ISNUMBER(E11),EDATE(E11,12),"") -> 46445 | I11: =IF(ISNUMBER(H11),H11-TODAY(),"") -> 131 | J11: =IF(ISNUMBER(H11),H11-90,"") -> 46355 | K11: =IF(ISNUMBER(H11),H11-30,"") -> 46415 | L11: =IF(C11="","",IF(M11="Renouvelé","Renouvelé",IF(M11="Perdu","Perdu",IF(NOT(ISNUMBER(H11)),"Date à confirmer",IF(H11<TODAY(),"Échu - urgent",IF(H11-TODAY()<=90,"À relancer (≤ 90 j)","À venir")))))) -> À venir | M11: Non démarré | P11: Préparer l’offre de renouvellement 2027 avant la relance J-90 | Q11: Premier contrat : 46 % du montant récurrent annuel. | R11: → CNAM
B12: 4 | C12: FER | D12: Licences ManageEngine | E12: =IF(ISNUMBER(FER!F34),FER!F34,"N/A") -> 46197 | F12: =IF(FER!G34="","",FER!G34) -> 28766400 | G12: 2026 : 28,8 M (nouveau client) | H12: =IF(ISNUMBER(E12),EDATE(E12,12),"") -> 46562 | I12: =IF(ISNUMBER(H12),H12-TODAY(),"") -> 248 | J12: =IF(ISNUMBER(H12),H12-90,"") -> 46472 | K12: =IF(ISNUMBER(H12),H12-30,"") -> 46532 | L12: =IF(C12="","",IF(M12="Renouvelé","Renouvelé",IF(M12="Perdu","Perdu",IF(NOT(ISNUMBER(H12)),"Date à confirmer",IF(H12<TODAY(),"Échu - urgent",IF(H12-TODAY()<=90,"À relancer (≤ 90 j)","À venir")))))) -> À venir | M12: Non démarré | P12: Point de satisfaction client avant la relance J-90 | R12: → FER
B13: 5 | C13: NSIA | D13: Licences ManageEngine | E13: =IF(ISNUMBER(NSIA!F45),NSIA!F45,"N/A") -> 46283 | F13: =IF(NSIA!G45="","",NSIA!G45) -> 1610068 | G13: 2024 : 1,0 M · 2025 : 1,0 M · 2026 : 1,6 M | H13: =IF(ISNUMBER(E13),EDATE(E13,12),"") -> 46648 | I13: =IF(ISNUMBER(H13),H13-TODAY(),"") -> 334 | J13: =IF(ISNUMBER(H13),H13-90,"") -> 46558 | K13: =IF(ISNUMBER(H13),H13-30,"") -> 46618 | L13: =IF(C13="","",IF(M13="Renouvelé","Renouvelé",IF(M13="Perdu","Perdu",IF(NOT(ISNUMBER(H13)),"Date à confirmer",IF(H13<TODAY(),"Échu - urgent",IF(H13-TODAY()<=90,"À relancer (≤ 90 j)","À venir")))))) -> À venir | M13: Non démarré | Q13: Renouvelle chaque année en septembre. | R13: → NSIA
B14: 6 | C14: CNAM | D14: Contrat de maintenance ManageEngine | E14: =IF(ISNUMBER(CNAM!F42),CNAM!F42,"N/A") -> N/A | F14: =IF(CNAM!G42="","",CNAM!G42) -> 18000000 | G14: 2025 : 18 M · 2026 : 18 M | I14: =IF(ISNUMBER(H14),H14-TODAY(),"") | J14: =IF(ISNUMBER(H14),H14-90,"") | K14: =IF(ISNUMBER(H14),H14-30,"") | L14: =IF(C14="","",IF(M14="Renouvelé","Renouvelé",IF(M14="Perdu","Perdu",IF(NOT(ISNUMBER(H14)),"Date à confirmer",IF(H14<TODAY(),"Échu - urgent",IF(H14-TODAY()<=90,"À relancer (≤ 90 j)","À venir")))))) -> Date à confirmer | M14: Non démarré | P14: Renseigner la date de facturation / d’échéance du contrat | Q14: Date de facturation « N/A » dans le point comptable : saisir l’échéance en colonne H. Solde 2026 de 4,5 M encore à encaisser. | R14: → CNAM
B15: =IF(C15="","",ROW()-8) | H15: =IF(ISNUMBER(E15),EDATE(E15,12),"") | I15: =IF(ISNUMBER(H15),H15-TODAY(),"") | J15: =IF(ISNUMBER(H15),H15-90,"") | K15: =IF(ISNUMBER(H15),H15-30,"") | L15: =IF(C15="","",IF(M15="Renouvelé","Renouvelé",IF(M15="Perdu","Perdu",IF(NOT(ISNUMBER(H15)),"Date à confirmer",IF(H15<TODAY(),"Échu - urgent",IF(H15-TODAY()<=90,"À relancer (≤ 90 j)","À venir"))))))
B16: =IF(C16="","",ROW()-8) | H16: =IF(ISNUMBER(E16),EDATE(E16,12),"") | I16: =IF(ISNUMBER(H16),H16-TODAY(),"") | J16: =IF(ISNUMBER(H16),H16-90,"") | K16: =IF(ISNUMBER(H16),H16-30,"") | L16: =IF(C16="","",IF(M16="Renouvelé","Renouvelé",IF(M16="Perdu","Perdu",IF(NOT(ISNUMBER(H16)),"Date à confirmer",IF(H16<TODAY(),"Échu - urgent",IF(H16-TODAY()<=90,"À relancer (≤ 90 j)","À venir"))))))
B17: =IF(C17="","",ROW()-8) | H17: =IF(ISNUMBER(E17),EDATE(E17,12),"") | I17: =IF(ISNUMBER(H17),H17-TODAY(),"") | J17: =IF(ISNUMBER(H17),H17-90,"") | K17: =IF(ISNUMBER(H17),H17-30,"") | L17: =IF(C17="","",IF(M17="Renouvelé","Renouvelé",IF(M17="Perdu","Perdu",IF(NOT(ISNUMBER(H17)),"Date à confirmer",IF(H17<TODAY(),"Échu - urgent",IF(H17-TODAY()<=90,"À relancer (≤ 90 j)","À venir"))))))
B18: =IF(C18="","",ROW()-8) | H18: =IF(ISNUMBER(E18),EDATE(E18,12),"") | I18: =IF(ISNUMBER(H18),H18-TODAY(),"") | J18: =IF(ISNUMBER(H18),H18-90,"") | K18: =IF(ISNUMBER(H18),H18-30,"") | L18: =IF(C18="","",IF(M18="Renouvelé","Renouvelé",IF(M18="Perdu","Perdu",IF(NOT(ISNUMBER(H18)),"Date à confirmer",IF(H18<TODAY(),"Échu - urgent",IF(H18-TODAY()<=90,"À relancer (≤ 90 j)","À venir"))))))
B19: =IF(C19="","",ROW()-8) | H19: =IF(ISNUMBER(E19),EDATE(E19,12),"") | I19: =IF(ISNUMBER(H19),H19-TODAY(),"") | J19: =IF(ISNUMBER(H19),H19-90,"") | K19: =IF(ISNUMBER(H19),H19-30,"") | L19: =IF(C19="","",IF(M19="Renouvelé","Renouvelé",IF(M19="Perdu","Perdu",IF(NOT(ISNUMBER(H19)),"Date à confirmer",IF(H19<TODAY(),"Échu - urgent",IF(H19-TODAY()<=90,"À relancer (≤ 90 j)","À venir"))))))
B20: =IF(C20="","",ROW()-8) | H20: =IF(ISNUMBER(E20),EDATE(E20,12),"") | I20: =IF(ISNUMBER(H20),H20-TODAY(),"") | J20: =IF(ISNUMBER(H20),H20-90,"") | K20: =IF(ISNUMBER(H20),H20-30,"") | L20: =IF(C20="","",IF(M20="Renouvelé","Renouvelé",IF(M20="Perdu","Perdu",IF(NOT(ISNUMBER(H20)),"Date à confirmer",IF(H20<TODAY(),"Échu - urgent",IF(H20-TODAY()<=90,"À relancer (≤ 90 j)","À venir"))))))
B21: TOTAL — montant récurrent annuel (base dernière facturation) | F21: =SUM(F9:F20) -> 143648024

Sheet CNAM
B2: CNAM — Fiche compte
B3: Client existant IAT | Montants en FCFA | Facturation et encaissements : point comptabilité au 13/10/2026
B4: Cellules jaune pâle = information à compléter · Texte vert = valeur reprise d’un autre onglet
B5: ← Retour à la synthèse
B7: 1. FICHE COMPTE
B8: Secteur | C8: Protection sociale / assurance maladie
B9: Direction générale (recherche du 15/10/2026) | C9: DG : Karim Bamba (confirmé) · DGA : Ahmed Tidiane Diomandé (confirmé)
B10: Interlocuteur direction (nom / fonction) | C10: Ismael Djiré / Directeur du système d'information
B11: Interlocuteur opérationnel (nom / fonction) | C11: Souleymane Cisse / Ingénieur système service administrateur
B12: Responsable IAT (lead commercial) | C12: Fadel Koloma / Salim Kone
B13: Relation haut niveau gérée par | C13: Mahoula
B14: État de santé du compte | C14: Bon
B15: Taux de satisfaction (1 à 5) | C15: 4
B16: Dernier contact
B17: Prochain point prévu | C17: Présentation et formation sur les solutions de la CNAM endpoint central et services deskplus
B18: Notes (réunion du 13/10/2026 et comptabilité) | C18: Premier client IAT : 46 % du montant récurrent annuel (compta). Contrats récurrents : licences ManageEngine (renouvellement annuel, prochaine échéance 27/02/2027) + contrat de maintenance facturé 4,5 M par trimestre. Un nouveau directeur est arrivé sur un compte suivi en haut par Maoula : le prendre en charge côté opérationnel (rattachement à la CNAM à confirmer).
B20: DIRIGEANTS — CNAM (Côte d’Ivoire) (recherche web + LinkedIn, données au 15/10/2026)
B21: Fonction | C21: Nom | E21: Fiabilité | F21: Source / remarque
B22: DG | C22: Karim Bamba | E22: Confirmé | F22: Site officiel (ipscnam.ci) ; pas de profil LinkedIn trouvé.
B23: DGA | C23: Ahmed Tidiane Diomandé | E23: Confirmé | F23: LinkedIn : Directeur Général Adjoint.
B24: DSI | C24: Ismael Djiré | E24: Confirmé | F24: directeur du système d'information et chef de service sécurité et infrastructure
B25: Directeur commercial | C25: — | E25: Non trouvé
B27: CONTACTS — BASE CLIENTS CI (aucun contact trouvé)
B28: Nom | C28: Fonction | E28: Profil | G28: Téléphone | I28: Email | L28: Commentaire
B29: Karim Bamba | C29: Directeur Général Adjoint | E29: Direction Générale
B30: Ahmed Tidiane Diomandé | C30: Directeur Général Adjoint | E30: Direction Générale
B31: Ismael Djiré | C31: Directeur du système d'information | E31: DirectionSI
B32: Souleymane Cisse | C32: Ingénieur système service administrateur | E32: Exploitation / infra | G32: +225 0555252468
B33: Malick Coulibaly | C33: Chef de service Projet | E33: Direction SI
B34: Naby Ouattara | C34: Chef cde service Helpdesk | E34: Direction SI | G34: +225 0758543513
B36: 2. CE QUI A DÉJÀ ÉTÉ VENDU ET FACTURÉ (historique, encaissements, récurrent / ponctuel)
B37: Produit / service | C37: Partenaire / éditeur | D37: Récurrent / ponctuel | E37: Exercice | F37: Date de facturation | G37: Montant facturé | H37: Coût des ventes | I37: Commission | J37: CA net | K37: Marge | L37: Encaissé | M37: Solde à encaisser | N37: Commentaires
B38: Licences ManageEngine (déploiement) | C38: ManageEngine | D38: Récurrent | E38: 2024 | F38: 45595 | G38: 69799690 | J38: =IF(G38="","",G38-N(I38)) -> 69799690 | K38: =IF(G38="","",J38-N(H38)) -> 69799690 | L38: 69799690 | M38: =IF(G38="","",G38-N(L38)) -> 0 | N38: Encaissé le 05/02/2025 (chèque 5770692).
B39: Licences ManageEngine | C39: ManageEngine | D39: Récurrent | E39: 2025 | F39: 45898 | G39: 66309706 | J39: =IF(G39="","",G39-N(I39)) -> 66309706 | K39: =IF(G39="","",J39-N(H39)) -> 66309706 | L39: 66309706 | M39: =IF(G39="","",G39-N(L39)) -> 0 | N39: Encaissé le 01/12/2025.
B40: Contrat de maintenance ManageEngine | C40: ManageEngine | D40: Récurrent | E40: 2025 | F40: N/A | G40: 18000000 | J40: =IF(G40="","",G40-N(I40)) -> 18000000 | K40: =IF(G40="","",J40-N(H40)) -> 18000000 | L40: 18000000 | M40: =IF(G40="","",G40-N(L40)) -> 0 | N40: Date de facturation non renseignée (N/A). Encaissé en déc. 2025 (9 M + 4,5 M + 4,5 M).
B41: Licences ManageEngine (renouvellement) | C41: ManageEngine | D41: Récurrent | E41: 2026 | F41: 46080 | G41: 66309707 | H41: 0 | I41: 33000000 | J41: =IF(G41="","",G41-N(I41)) -> 33309707 | K41: =IF(G41="","",J41-N(H41)) -> 33309707 | L41: 66309707 | M41: =IF(G41="","",G41-N(L41)) -> 0 | N41: Soldé. Coût des ventes et commission repris du pipeline d’origine.
B42: Contrat de maintenance ManageEngine | C42: ManageEngine | D42: Récurrent | E42: 2026 | F42: N/A | G42: 18000000 | H42: 500000 | I42: 6000000 | J42: =IF(G42="","",G42-N(I42)) -> 12000000 | K42: =IF(G42="","",J42-N(H42)) -> 11500000 | L42: 13500000 | M42: =IF(G42="","",G42-N(L42)) -> 4500000 | N42: Facturation trimestrielle de 4,5 M. Solde de 4,5 M à relancer auprès de la direction financière (échéance 01/12/2026). Date de facturation à renseigner.
J43: =IF(G43="","",G43-N(I43)) | K43: =IF(G43="","",J43-N(H43)) | M43: =IF(G43="","",G43-N(L43))
J44: =IF(G44="","",G44-N(I44)) | K44: =IF(G44="","",J44-N(H44)) | M44: =IF(G44="","",G44-N(L44))
B45: TOTAL FACTURÉ (tous exercices) | G45: =SUM(G38:G44) -> 238419103 | H45: =SUM(H38:H44) -> 500000 | I45: =SUM(I38:I44) -> 39000000 | J45: =SUM(J38:J44) -> 199419103 | K45: =SUM(K38:K44) -> 198919103 | L45: =SUM(L38:L44) -> 233919103 | M45: =SUM(M38:M44) -> 4500000
...

Sheet CNPS
B2: CNPS — Fiche compte
B3: Client existant IAT | Montants en FCFA | Facturation et encaissements : point comptabilité au 13/10/2026
B4: Cellules jaune pâle = information à compléter · Texte vert = valeur reprise d’un autre onglet
B5: ← Retour à la synthèse
B7: 1. FICHE COMPTE
B8: Secteur | C8: Protection sociale
B9: Direction générale (recherche du 15/10/2026) | C9: DG : Denis Charles Kouassi (confirmé) · DGA chargé de l’exploitation : Idriss Traoré (à confirmer) · DSI : Thierry Bahi (à confirmer)
B10: Interlocuteur direction (nom / fonction) | C10: Gballet BEUGRE — Directeur du Système d'Information (DSI) (base clients — coordonnées ci-dessous)
B11: Interlocuteur opérationnel (nom / fonction) | C11: Innocent YAPI — RSSI ; Amadou DIOMANDOU — Chef de Departement Infrastructure et Exploitation ; Daouda COULIBALY — Chef du Service Système Réseau et NTIC (base clients)
B12: Achats / marchés | C12: Nomel Lorgn Florent — Acheteur ; Mme YASSI Née DIALLO — Resp Chargés des Marchés (base clients)
B13: Responsable IAT (lead commercial) | C13: Fadel Koloma / Salim Kone
B14: Relation haut niveau gérée par
B15: État de santé du compte
B16: Taux de satisfaction (1 à 5)
B17: Dernier contact
B18: Prochain point prévu
B19: Notes (réunion du 13/10/2026 et comptabilité) | C19: Renouvellement des licences échu depuis le 10/02/2026 : offre 2026 envoyée, en attente de retour (compta). La réunion du 13/10 évoque un contrat de 22 700 000 envoyé à la signature et une autre offre d’environ 59 M non validée. Le montant du renouvellement n’est pas chiffré dans le point comptable : à rapprocher.
B21: DIRIGEANTS — CNPS (Côte d’Ivoire) (recherche web + LinkedIn, données au 15/10/2026)
B22: Fonction | C22: Nom | E22: Fiabilité | F22: Source / remarque
B23: DG | C23: Denis Charles Kouassi | E23: Confirmé | F23: LinkedIn + presse.
B24: DGA chargé de l’exploitation | C24: Idriss Traoré | E24: À confirmer | F24: Profil LinkedIn en lecture limitée.
B25: DSI | C25: Thierry Bahi | E25: À confirmer | F25: Cité en déc. 2023, introuvable sur LinkedIn. ⚠ La base clients CI indique Gballet BEUGRE comme DSI : à trancher.
B26: Directeur commercial | C26: — | E26: Non trouvé
B28: CONTACTS — BASE CLIENTS CI (CNPS)
B29: Nom | C29: Fonction | E29: Profil | G29: Téléphone | I29: Email | L29: Commentaire
B30: Gballet BEUGRE | C30: Directeur du Système d'Information (DSI) | E30: Direction SI / digital | G30: Cel:(225)08305255 | I30: g.beugre@cnps.ci | L30: La recherche web du 15/10/2026 cite Thierry Bahi comme DSI (à confirmer) : vérifier qui est en poste.
B31: Innocent YAPI | C31: RSSI | E31: Sécurité SI | G31: 08 30 57 79 | I31: i.yapi@cnps.ci | L31: Numéro au format à 8 chiffres (avant 2021) : à mettre à jour
B32: Amadou DIOMANDOU | C32: Chef de Departement Infrastructure et Exploitation | E32: Infrastructure / réseaux | G32: 0779 42 41 00 / 014307744 | I32: a.diomande@cnps.ci
B33: Daouda COULIBALY | C33: Chef du Service Système Réseau et NTIC | E33: Infrastructure / réseaux | G33: CEL: +225 57887371 | I33: d.coulibaly@cnps.ci | L33: Numéro au format à 8 chiffres (avant 2021) : à mettre à jour
B34: Nomel Lorgn Florent | C34: Acheteur | E34: Achats / marchés | G34: 07 57 45 52 82 | I34: f.nomel@cnps.ci
B35: Mme YASSI Née DIALLO | C35: Resp Chargés des Marchés | E35: Achats / marchés | I35: k.diallo@cnps.ci
B36: DRAME | C36: Resp Sce Formation | E36: Commercial / autre | G36: 07 65 38 98 | I36: y.drame@cnps.ci | L36: Numéro au format à 8 chiffres (avant 2021) : à mettre à jour
B37: POLL Hermann SEKA SEKA | E37: Non renseigné | G37: 07 59 34 55 44 | I37: p.seka@cnps.ci
B39: 2. CE QUI A DÉJÀ ÉTÉ VENDU ET FACTURÉ (historique, encaissements, récurrent / ponctuel)
B40: Produit / service | C40: Partenaire / éditeur | D40: Récurrent / ponctuel | E40: Exercice | F40: Date de facturation | G40: Montant facturé | H40: Coût des ventes | I40: Commission | J40: CA net | K40: Marge | L40: Encaissé | M40: Solde à encaisser | N40: Commentaires
B41: Licences ManageEngine | C41: ManageEngine | D41: Récurrent | E41: 2025 | F41: 45698 | G41: 21578849 | J41: =IF(G41="","",G41-N(I41)) -> 21578849 | K41: =IF(G41="","",J41-N(H41)) -> 21578849 | L41: 21578849 | M41: =IF(G41="","",G41-N(L41)) -> 0 | N41: Encaissé le 18/03/2025.
J42: =IF(G42="","",G42-N(I42)) | K42: =IF(G42="","",J42-N(H42)) | M42: =IF(G42="","",G42-N(L42))
J43: =IF(G43="","",G43-N(I43)) | K43: =IF(G43="","",J43-N(H43)) | M43: =IF(G43="","",G43-N(L43))
J44: =IF(G44="","",G44-N(I44)) | K44: =IF(G44="","",J44-N(H44)) | M44: =IF(G44="","",G44-N(L44))
B45: TOTAL FACTURÉ (tous exercices) | G45: =SUM(G41:G44) -> 21578849 | H45: =SUM(H41:H44) -> 0 | I45: =SUM(I41:I44) -> 0 | J45: =SUM(J41:J44) -> 21578849 | K45: =SUM(K41:K44) -> 21578849 | L45: =SUM(L41:L44) -> 21578849 | M45: =SUM(M41:M44) -> 0
...

Sheet FER
B2: FER — Fiche compte
B3: Client existant IAT | Montants en FCFA | Facturation et encaissements : point comptabilité au 13/10/2026
B4: Cellules jaune pâle = information à compléter · Texte vert = valeur reprise d’un autre onglet
B5: ← Retour à la synthèse
B7: 1. FICHE COMPTE
B8: Secteur | C8: Administration / infrastructures routières (Fonds d’entretien routier)
B9: Direction générale (recherche du 15/10/2026) | C9: Directrice générale : Annick Tohé Lasmel (confirmé) · Directeur financier et comptable : Moussa Diarra (à confirmer)
B10: Interlocuteur direction (nom / fonction)
B11: Interlocuteur opérationnel (nom / fonction)
B12: Responsable IAT (lead commercial) | C12: Commercial IAT
B13: Relation haut niveau gérée par
B14: État de santé du compte
B15: Taux de satisfaction (1 à 5)
B16: Dernier contact
B17: Prochain point prévu
B18: Notes (réunion du 13/10/2026 et comptabilité) | C18: Nouveau client 2026 (compta) : licences ManageEngine facturées 28 766 400 le 24/06/2026, soldées. Prochaine échéance 24/06/2027. La sécurisation des boîtes mail était le produit d’entrée ; une formation sur la solution était prévue.
B20: DIRIGEANTS — FER (Côte d’Ivoire) (recherche web + LinkedIn, données au 15/10/2026)
B21: Fonction | C21: Nom | E21: Fiabilité | F21: Source / remarque
B22: Directrice générale | C22: Annick Tohé Lasmel | E22: Confirmé | F22: Site officiel du FER (actif juillet 2026) ; dirige le FER depuis 2022 ; pas de profil LinkedIn.
B23: Directeur financier et comptable | C23: Moussa Diarra | E23: À confirmer | F23: Information complémentaire de la recherche.
B24: DGA | C24: — | E24: Non trouvé
B25: DSI | C25: — | E25: Non trouvé | F25: Aucun DSI trouvé : à identifier (porte d’entrée naturelle pour ManageEngine).
B26: Directeur commercial | C26: — | E26: Non trouvé
B28: CONTACTS — BASE CLIENTS CI (aucun contact trouvé)
B29: Nom | C29: Fonction | E29: Profil | G29: Téléphone | I29: Email | L29: Commentaire
B30: Aucun contact dans la base clients CI : à compléter
B32: 2. CE QUI A DÉJÀ ÉTÉ VENDU ET FACTURÉ (historique, encaissements, récurrent / ponctuel)
B33: Produit / service | C33: Partenaire / éditeur | D33: Récurrent / ponctuel | E33: Exercice | F33: Date de facturation | G33: Montant facturé | H33: Coût des ventes | I33: Commission | J33: CA net | K33: Marge | L33: Encaissé | M33: Solde à encaisser | N33: Commentaires
B34: Licences ManageEngine | C34: ManageEngine | D34: Récurrent | E34: 2026 | F34: 46197 | G34: 28766400 | J34: =IF(G34="","",G34-N(I34)) -> 28766400 | K34: =IF(G34="","",J34-N(H34)) -> 28766400 | L34: 28766400 | M34: =IF(G34="","",G34-N(L34)) -> 0 | N34: Soldé. Nouveau client 2026.
J35: =IF(G35="","",G35-N(I35)) | K35: =IF(G35="","",J35-N(H35)) | M35: =IF(G35="","",G35-N(L35))
J36: =IF(G36="","",G36-N(I36)) | K36: =IF(G36="","",J36-N(H36)) | M36: =IF(G36="","",G36-N(L36))
J37: =IF(G37="","",G37-N(I37)) | K37: =IF(G37="","",J37-N(H37)) | M37: =IF(G37="","",G37-N(L37))
B38: TOTAL FACTURÉ (tous exercices) | G38: =SUM(G34:G37) -> 28766400 | H38: =SUM(H34:H37) -> 0 | I38: =SUM(I34:I37) -> 0 | J38: =SUM(J34:J37) -> 28766400 | K38: =SUM(K34:K37) -> 28766400 | L38: =SUM(L34:L37) -> 28766400 | M38: =SUM(M34:M37) -> 0
B39: dont exercice 2026 | G39: =SUMIFS(G34:G37,$E$34:$E$37,2026) -> 28766400 | I39: =SUMIFS(I34:I37,$E$34:$E$37,2026) -> 0 | K39: =SUMIFS(K34:K37,$E$34:$E$37,2026) -> 28766400 | L39: =SUMIFS(L34:L37,$E$34:$E$37,2026) -> 28766400 | M39: =SUMIFS(M34:M37,$E$34:$E$37,2026) -> 0
B41: 3. OFFRES EN COURS / À SUIVRE (envoyées, non encore validées, renouvellements)
B42: Offre / affaire | C42: Partenaire / éditeur | D42: Étape | E42: Date d’envoi | F42: Échéance décision | G42: Montant | H42: Closing | I42: Montant pondéré | J42: Responsable | K42: Prochaine étape | N42: Commentaires
B43: Sécurisation des boîtes mail | C43: ManageEngine | D43: M5 – Négociation / signature | G43: 4500000 | H43: 0.9 | I43: =IF(OR(G43="",H43=""),"",G43*H43) -> 4050000 | J43: Commercial IAT | K43: Vérifier avec la compta si ce montant est inclus dans les 28,8 M facturés ou reste à facturer. | N43: Ligne du pipeline d’origine (fiabilité 90 %, coût des ventes 1 065 000, commission 0) non retrouvée dans la facturation transmise.
B44: Formation sur la solution de sécurisation mail | C44: ManageEngine | D44: M3 – Offre en préparation | I44: =IF(OR(G44="",H44=""),"",G44*H44) | J44: Commercial IAT | K44: Planifier la formation et l’utiliser pour détecter d’autres besoins.
I45: =IF(OR(G45="",H45=""),"",G45*H45)
I46: =IF(OR(G46="",H46=""),"",G46*H46)
...

Sheet NSIA
A1: 0
B2: NSIA — Fiche compte
B3: Client existant IAT | Montants en FCFA | Facturation et encaissements : point comptabilité au 13/10/2026
B4: Cellules jaune pâle = information à compléter · Texte vert = valeur reprise d’un autre onglet
B5: ← Retour à la synthèse
B7: 1. FICHE COMPTE
B8: Secteur | C8: Assurance
B9: Direction générale (recherche du 15/10/2026) | C9: DG : Sonia Nadège Seka (à confirmer) · DGA : Gérard Gilles Akou (confirmé) · Directeur du réseau des particuliers : Jacques Avenie (à confirmer)
B10: Interlocuteur direction (nom / fonction) | C10: Gabriel COMOE-EDANOU — Directeur Des Opérations et de la Technologies Groupe (base clients — coordonnées ci-dessous)
B11: Interlocuteur opérationnel (nom / fonction) | C11: Tyao Basile N'GUESSSAN — Ingénieur Projet ; AMANGOUA Alexandre ; Elvis Adou (base clients)
B12: Achats / marchés
B13: Responsable IAT (lead commercial) | C13: Commercial IAT
B14: Relation haut niveau gérée par
B15: État de santé du compte
B16: Taux de satisfaction (1 à 5)
B17: Dernier contact
B18: Prochain point prévu
B19: Notes (réunion du 13/10/2026 et comptabilité) | C19: Client récurrent depuis 2024 (compta), renouvelle chaque année en septembre. Raisons sociales facturées : NSIA Assurances (2024-2025) puis NSIA Assurances Vie (2026). Figurait comme prospect « NSIA VIE » dans l’ancien pipeline.
B21: DIRIGEANTS — NSIA Vie (Côte d’Ivoire) (recherche web + LinkedIn, données au 15/10/2026)
B22: Fonction | C22: Nom | E22: Fiabilité | F22: Source / remarque
B23: DG | C23: Sonia Nadège Seka | E23: À confirmer | F23: Profil LinkedIn limité, filiale non certifiée : à recouper.
B24: DGA | C24: Gérard Gilles Akou | E24: Confirmé | F24: LinkedIn : DGA NSIA Vie CI (n’est plus directeur commercial).
B25: Directeur du réseau des particuliers | C25: Jacques Avenie | E25: À confirmer | F25: Équivalent le plus proche d’un directeur commercial.
B26: Directeur financier | C26: Richmond Fabrice N’Doua | E26: À confirmer
B27: Directeur études, réassurance et actuariat | C27: Konan Manassé Yao | E27: À confirmer | F27: Interlocuteur clé pour le pitch Credolab Assurance (atelier avec les équipes actuarielles).
B28: DG NSIA Holding Assurances (groupe) | C28: Mansan Dominique Diagou-Ehilé | E28: À confirmer | F28: N’est plus DG de NSIA Vie CI.
B29: DSI | C29: — | E29: Non trouvé | F29: Ancien DSI : Edna Adou Tehia (poste précédent) ; Mohamed Coulibaly n’apparaît plus.
B31: CONTACTS — BASE CLIENTS CI (NSIA Banque, NSIA PARTICIPATION)
B32: Nom | C32: Fonction | E32: Profil | G32: Téléphone | I32: Email | L32: Commentaire
B33: Gabriel COMOE-EDANOU | C33: Directeur Des Opérations et de la Technologies Groupe | E33: Direction SI / digital | G33: 0749595963 | I33: gabriel.comoe-edanou@groupensia.com
B34: Tyao Basile N'GUESSSAN | C34: Ingénieur Projet | E34: Informatique / projets | G34: 0505 89 35 46 | I34: basile.nguessan@groupensia.com
B35: AMANGOUA Alexandre | E35: Non renseigné | G35: 07 88 86 46 22 | I35: alexandre.armangouah@groupensia.com
B36: Elvis Adou | E36: Non renseigné | G36: 0709243281 | I36: elvis.adou@nsiabanque.com
B37: Eric AHUI | E37: Non renseigné | G37: 07 69 28 66 02 | I37: eric.ahui@nsiabanque.com
B38: Francis gnakoury | E38: Non renseigné | G38: 0787530619 | I38: francis.gnakouri@nsiabanque.com
B39: Prosper Yao | E39: Non renseigné | G39: 0708013119 | I39: prosper.yao@groupensia.com
B41: 2. CE QUI A DÉJÀ ÉTÉ VENDU ET FACTURÉ (historique, encaissements, récurrent / ponctuel)
B42: Produit / service | C42: Partenaire / éditeur | D42: Récurrent / ponctuel | E42: Exercice | F42: Date de facturation | G42: Montant facturé | H42: Coût des ventes | I42: Commission | J42: CA net | K42: Marge | L42: Encaissé | M42: Solde à encaisser | N42: Commentaires
B43: Licences ManageEngine | C43: ManageEngine | D43: Récurrent | E43: 2024 | F43: 45560 | G43: 1003000 | J43: =IF(G43="","",G43-N(I43)) -> 1003000 | K43: =IF(G43="","",J43-N(H43)) -> 1003000 | L43: 1003000 | M43: =IF(G43="","",G43-N(L43)) -> 0 | N43: NSIA ASSURANCES — soldé.
B44: Licences ManageEngine | C44: ManageEngine | D44: Récurrent | E44: 2025 | F44: 45905 | G44: 982940 | J44: =IF(G44="","",G44-N(I44)) -> 982940 | K44: =IF(G44="","",J44-N(H44)) -> 982940 | L44: 982940 | M44: =IF(G44="","",G44-N(L44)) -> 0 | N44: Encaissé le 24/09/2025.
...

Sheet Orange Business
B2: Orange Business — Fiche compte
B3: Client existant IAT | Montants en FCFA
B4: Cellules jaune pâle = information à compléter · Texte vert = valeur reprise d’un autre onglet
B5: ← Retour à la synthèse
B7: 1. FICHE COMPTE
